<mujoco model="pendulum">
  <compiler angle="radian"/>
  <statistic meansize="0.250205" extent="1.0008" center="0 0 -0.5"/>
  <worldbody>
    <body name="base">
      <inertial pos="0 0 0" mass="2" diaginertia="1 1 1"/>
      <body name="pendulum_link">
        <inertial pos="0 0 -0.5" mass="1" diaginertia="0.083433 0.083433 0.0002"/>
        <joint name="pendulum_joint" pos="0 0 0" axis="0 1 0" />
        <geom name="pendulum_link_visual" size="0.02 0.5" pos="0 0 -0.5" 
              type="cylinder" contype="0" conaffinity="0" group="1" density="0" 
              rgba="1 0 0 1"/>
      </body>
    </body>
    <light name="top" pos="0 0 1" />
    <light name="front" pos="0 1 0" />
  </worldbody>
  <actuator>
    <motor ctrllimited="true" ctrlrange="-0.1 0.1" name="pendulum_joint" joint="pendulum_joint" gear="10"/>
  </actuator>
</mujoco>